{"timestamp": "2017-12-13T09:32:27.350287Z", "level": "CRITICAL", "message": "Unhandled exception: %s", "system": "Windows 10", "gh_handle": "DonBattery", "command": "C:\\Users\\Miki\\AppData\\Local\\Programs\\Python\\Python36-32\\Scripts\\gf start https://github.com/greenfox-academy/badcat-syllabus/wiki/Week-4", "feature": "START", "workshop_url": "https://github.com/greenfox-academy/badcat-syllabus/wiki/Week-4", "language": null, "type": "<class 'TimeoutError'>", "value": "Exception: [WinError 10060] A kapcsol\u00f3d\u00e1si k\u00eds\u00e9rlet nem siker\u00fclt, mert a kapcsol\u00f3d\u00f3 partner nem v\u00e1laszolt a megadott id\u0151n bel\u00fcl, vagy a l\u00e9trehozott kapcsolatban hiba t\u00f6rt\u00e9nt, mert a kapcsol\u00f3d\u00f3 partner nem volt k\u00e9pes v\u00e1laszolni", "traceback": "File \"c:\\users\\miki\\appdata\\local\\programs\\python\\python36-32\\lib\\runpy.py\", line 193, in _run_module_as_main\n    \"__main__\", mod_spec)\n  File \"c:\\users\\miki\\appdata\\local\\programs\\python\\python36-32\\lib\\runpy.py\", line 85, in _run_code\n    exec(code, run_globals)\n  File \"C:\\Users\\Miki\\AppData\\Local\\Programs\\Python\\Python36-32\\Scripts\\gf.exe\\__main__.py\", line 9, in <module>\n    sys.exit(main())\n  File \"c:\\users\\miki\\appdata\\local\\programs\\python\\python36-32\\lib\\site-packages\\gf\\app_starter.py\", line 13, in main\n    logger.info(\"Application start\")\n  File \"c:\\users\\miki\\appdata\\local\\programs\\python\\python36-32\\lib\\site-packages\\external\\local\\logger.py\", line 125, in info\n    self._log(\"info\", extra)\n  File \"c:\\users\\miki\\appdata\\local\\programs\\python\\python36-32\\lib\\site-packages\\external\\local\\logger.py\", line 117, in _log\n    log(message)\n  File \"c:\\users\\miki\\appdata\\local\\programs\\python\\python36-32\\lib\\logging\\__init__.py\", line 1306, in info\n    self._log(INFO, msg, args, **kwargs)\n  File \"c:\\users\\miki\\appdata\\local\\programs\\python\\python36-32\\lib\\logging\\__init__.py\", line 1442, in _log\n    self.handle(record)\n  File \"c:\\users\\miki\\appdata\\local\\programs\\python\\python36-32\\lib\\logging\\__init__.py\", line 1452, in handle\n    self.callHandlers(record)\n  File \"c:\\users\\miki\\appdata\\local\\programs\\python\\python36-32\\lib\\logging\\__init__.py\", line 1514, in callHandlers\n    hdlr.handle(record)\n  File \"c:\\users\\miki\\appdata\\local\\programs\\python\\python36-32\\lib\\logging\\__init__.py\", line 863, in handle\n    self.emit(record)\n  File \"c:\\users\\miki\\appdata\\local\\programs\\python\\python36-32\\lib\\site-packages\\external\\local\\elastic_log_handler.py\", line 14, in emit\n    http_request_handling(\"log_post_elk\", body, elk_id=\"\")\n  File \"c:\\users\\miki\\appdata\\local\\programs\\python\\python36-32\\lib\\site-packages\\external\\web\\http_request_handler.py\", line 15, in http_request_handling\n    http_connection.request(method, url, body, header)\n  File \"c:\\users\\miki\\appdata\\local\\programs\\python\\python36-32\\lib\\http\\client.py\", line 1239, in request\n    self._send_request(method, url, body, headers, encode_chunked)\n  File \"c:\\users\\miki\\appdata\\local\\programs\\python\\python36-32\\lib\\http\\client.py\", line 1285, in _send_request\n    self.endheaders(body, encode_chunked=encode_chunked)\n  File \"c:\\users\\miki\\appdata\\local\\programs\\python\\python36-32\\lib\\http\\client.py\", line 1234, in endheaders\n    self._send_output(message_body, encode_chunked=encode_chunked)\n  File \"c:\\users\\miki\\appdata\\local\\programs\\python\\python36-32\\lib\\http\\client.py\", line 1026, in _send_output\n    self.send(msg)\n  File \"c:\\users\\miki\\appdata\\local\\programs\\python\\python36-32\\lib\\http\\client.py\", line 964, in send\n    self.connect()\n  File \"c:\\users\\miki\\appdata\\local\\programs\\python\\python36-32\\lib\\http\\client.py\", line 936, in connect\n    (self.host,self.port), self.timeout, self.source_address)\n  File \"c:\\users\\miki\\appdata\\local\\programs\\python\\python36-32\\lib\\socket.py\", line 724, in create_connection\n    raise err\n  File \"c:\\users\\miki\\appdata\\local\\programs\\python\\python36-32\\lib\\socket.py\", line 713, in create_connection\n    sock.connect(sa)"}
